<mujocoinclude>
    <body name="left_arm_1">
        <geom mesh="left_arm_1_0" material="69,69,69_8.001" class="visual" />
        <geom mesh="left_arm_1_1" material="75,75,75_70.001" class="visual" />
        <geom mesh="left_arm_1_2" material="75,75,75_69.001" class="visual" />
        <geom mesh="left_arm_1_3" material="75,75,75_68.001" class="visual" />
        <geom mesh="left_arm_1_4" material="39,39,39_11.001" class="visual" />
        <!-- <geom mesh="left_arm_1_0" class="collision" />
        <geom mesh="left_arm_1_1" class="collision" />
        <geom mesh="left_arm_1_2" class="collision" />
        <geom mesh="left_arm_1_3" class="collision" />
        <geom mesh="left_arm_1_4" class="collision" /> -->

        <inertial pos="0.18478 -0.15233 1.0767" mass="1.0" diaginertia="1 1 1" />
        <joint name="left_arm_1_joint" pos="0.083 -0.154 1.04"
            axis="0.944200181445777 0 0.329372156318292" />

        <body name="left_arm_2">
            <geom mesh="left_arm_2_0" material="75,75,75_67.001" class="visual" />
            <geom mesh="left_arm_2_1" material="39,39,39_10.001" class="visual" />
            <geom mesh="left_arm_2_2" material="39,39,39_12.001" class="visual" />
            <geom mesh="left_arm_2_3" material="75,75,75_71.001" class="visual" />
            <!-- <geom mesh="left_arm_2_0" class="collision" />
            <geom mesh="left_arm_2_1" class="collision" />
            <geom mesh="left_arm_2_2" class="collision" />
            <geom mesh="left_arm_2_3" class="collision" /> -->

            <inertial pos="0.22495 -0.1403 1.0664" mass="1.0" diaginertia="1 1 1" />
            <joint name="left_arm_2_joint" pos="0.22 -0.22 1.09" axis="0 -1 0" />

            <body name="left_arm_3">
                <geom mesh="left_arm_3_0" material="69,69,69_9.001" class="visual" />
                <geom mesh="left_arm_3_1" material="254,254,255_55.001" class="visual" />
                <geom mesh="left_arm_3_2" material="75,75,75_65.001" class="visual" />
                <geom mesh="left_arm_3_3" material="75,75,75_66.001" class="visual" />
                <geom mesh="left_arm_3_4" material="247,247,247_54.001" class="visual" />
                <geom mesh="left_arm_3_5" material="247,247,247_55.001" class="visual" />
                <geom mesh="left_arm_3_6" material="75,75,75_64.001" class="visual" />
                <geom mesh="left_arm_3_7" material="247,247,247_56.001" class="visual" />
                <geom mesh="left_arm_3_8" material="247,247,247_58.001" class="visual" />
                <geom mesh="left_arm_3_9" material="247,247,247_57.001" class="visual" />
                <!-- <geom mesh="left_arm_3_0" class="collision" />
                <geom mesh="left_arm_3_1" class="collision" />
                <geom mesh="left_arm_3_2" class="collision" />
                <geom mesh="left_arm_3_3" class="collision" />
                <geom mesh="left_arm_3_4" class="collision" />
                <geom mesh="left_arm_3_5" class="collision" />
                <geom mesh="left_arm_3_6" class="collision" />
                <geom mesh="left_arm_3_7" class="collision" />
                <geom mesh="left_arm_3_8" class="collision" />
                <geom mesh="left_arm_3_9" class="collision" /> -->

                <inertial pos="0.2221 -0.15571 0.88123" mass="1.0" diaginertia="1 1 1" />
                <joint name="left_arm_3_joint" pos="0.22 -0.154 0.99" axis="0 0 1" />

                <body name="left_arm_4">
                    <geom mesh="left_arm_4_0" material="39,39,39_8.001" class="visual" />
                    <geom mesh="left_arm_4_1" material="247,247,247_52.001" class="visual" />
                    <geom mesh="left_arm_4_2" material="247,247,247_51.001" class="visual" />
                    <geom mesh="left_arm_4_3" material="75,75,75_63.001" class="visual" />
                    <geom mesh="left_arm_4_4" material="247,247,247_53.001" class="visual" />
                    <geom mesh="left_arm_4_5" material="39,39,39_9.001" class="visual" />
                    <!-- <geom mesh="left_arm_4_0" class="collision" />
                    <geom mesh="left_arm_4_1" class="collision" />
                    <geom mesh="left_arm_4_2" class="collision" />
                    <geom mesh="left_arm_4_3" class="collision" />
                    <geom mesh="left_arm_4_4" class="collision" />
                    <geom mesh="left_arm_4_5" class="collision" /> -->

                    <inertial pos="0.21944 -0.22938 0.80409" mass="1.0" diaginertia="1 1 1" />
                    <!-- <joint name="left_arm_4_joint" pos="0.282 -0.185 0.814" axis="1 0 0"
                        ref="-1.90949408420305" /> -->
                    <joint name="left_arm_4_joint" pos="0.282 -0.185 0.814" axis="1 0 0"
                        ref="0" />

                    <body name="left_arm_5">
                        <geom mesh="left_arm_5_0" material="247,247,247_50.001" class="visual" />
                        <geom mesh="left_arm_5_1" material="247,247,247_45.001" class="visual" />
                        <geom mesh="left_arm_5_2" material="247,247,247_46.001" class="visual" />
                        <geom mesh="left_arm_5_3" material="247,247,247_48.001" class="visual" />
                        <geom mesh="left_arm_5_4" material="247,247,247_47.001" class="visual" />
                        <geom mesh="left_arm_5_5" material="247,247,247_49.001" class="visual" />
                        <!-- <geom mesh="left_arm_5_0" class="collision" />
                        <geom mesh="left_arm_5_1" class="collision" />
                        <geom mesh="left_arm_5_2" class="collision" />
                        <geom mesh="left_arm_5_3" class="collision" />
                        <geom mesh="left_arm_5_4" class="collision" />
                        <geom mesh="left_arm_5_5" class="collision" /> -->

                        <inertial pos="0.24074 -0.39082 0.85342" mass="1.0" diaginertia="1 1 1" />
                        <joint name="left_arm_5_joint" pos="0.22 -0.243 0.801"
                            axis="0 0.943188038541758 -0.332259422668118" />

                        <body name="left_arm_6">
                            <geom mesh="left_arm_6_0" material="75,75,75_56.001" class="visual" />
                            <geom mesh="left_arm_6_1" material="75,75,75_61.001" class="visual" />
                            <geom mesh="left_arm_6_2" material="75,75,75_58.001" class="visual" />
                            <geom mesh="left_arm_6_3" material="75,75,75_57.001" class="visual" />
                            <geom mesh="left_arm_6_4" material="39,39,39_7.001" class="visual" />
                            <geom mesh="left_arm_6_5" material="254,254,255_50.001" class="visual" />
                            <geom mesh="left_arm_6_6" material="75,75,75_62.001" class="visual" />
                            <geom mesh="left_arm_6_7" material="247,247,247_44.001" class="visual" />
                            <geom mesh="left_arm_6_8" material="152,170,175_10.001" class="visual" />
                            <geom mesh="left_arm_6_9" material="75,75,75_60.001" class="visual" />
                            <!-- <geom mesh="left_arm_6_0" class="collision" />
                            <geom mesh="left_arm_6_1" class="collision" />
                            <geom mesh="left_arm_6_2" class="collision" />
                            <geom mesh="left_arm_6_3" class="collision" />
                            <geom mesh="left_arm_6_4" class="collision" />
                            <geom mesh="left_arm_6_5" class="collision" />
                            <geom mesh="left_arm_6_6" class="collision" />
                            <geom mesh="left_arm_6_7" class="collision" />
                            <geom mesh="left_arm_6_8" class="collision" />
                            <geom mesh="left_arm_6_9" class="collision" /> -->

                            <inertial pos="0.2203 -0.45656 0.83282" mass="0.5"
                                diaginertia="0.5 0.5 0.5" />
                            <!-- <joint name="left_arm_6_joint" pos="0.254 -0.436 0.869" axis="1 0 0"
                                ref="1.206239456233958" /> -->

                            <joint name="left_arm_6_joint" pos="0.254 -0.436 0.869" axis="1 0 0"
                                ref="0" />

                            <body name="left_arm_7">
                                <geom mesh="left_arm_7_0" material="70,70,70_2.001" class="visual" />
                                <geom mesh="left_arm_7_1" material="75,75,75_78.001" class="visual" />
                                <geom mesh="left_arm_7_2" material="39,39,39_6.001" class="visual" />
                                <!-- <geom mesh="left_arm_7_0" class="collision" />
                                <geom mesh="left_arm_7_1" class="collision" />
                                <geom mesh="left_arm_7_2" class="collision" /> -->

                                <inertial pos="0.22244 -0.51964 0.77099" mass="0.1"
                                    diaginertia="0.1 0.1 0.1" />
                                <!-- <joint name="left_arm_7_joint" pos="0.22 -0.489265 0.807236"
                                    axis="0 0.648977564336161 0.760807545301901" ref="1.570796327" /> -->
                                <joint name="left_arm_7_joint" pos="0.22 -0.489265 0.807236"
                                    axis="0 0.648977564336161 0.760807545301901" ref="0" />

                                <site name="left_tcp" pos="0.22 -0.578 0.709"
                                    euler="-0.706239456233958 0 -1.570796327" />

                                <body name="left_arm_f1">
                                    <geom mesh="left_arm_f1_0" material="70,70,70_1.003" class="visual" />
                                    <geom mesh="left_arm_f1_1" material="75,75,75_1.003" class="visual" />
                                    <geom mesh="left_arm_f1_0" class="collision" />
                                    <geom mesh="left_arm_f1_1" class="collision" />

                                    <inertial pos="0.16471 -0.5604 0.72393" mass="0.01"
                                        diaginertia="0.01 0.01 0.01" />
                                    <joint name="left_arm_f1_joint" type="slide"
                                        pos="0.282 -0.572 0.704" axis="1 0 0"
                                        range="0 0.05" limited="true"/>
                                </body>

                                <body name="left_arm_f2">
                                    <geom mesh="left_arm_f2_0" material="70,70,70_1.002" class="visual" />
                                    <geom mesh="left_arm_f2_1" material="75,75,75_1.002" class="visual" />
                                    <geom mesh="left_arm_f2_0" class="collision" />
                                    <geom mesh="left_arm_f2_1" class="collision" />

                                    <inertial pos="0.27529 -0.5604 0.72393" mass="0.01"
                                        diaginertia="0.01 0.01 0.01" />
                                    <joint name="left_arm_f2_joint" type="slide"
                                        pos="0.282 -0.572 0.704" axis="1 0 0"
                                        range="-0.05 0" limited="true"/>
                                </body>
                            </body>
                        </body>
                    </body>
                </body>
            </body>
        </body>
    </body>
</mujocoinclude>